Workbook

Sheet Instructions
B2: ISV Discovery Workbook
B3: Document every software product your company pays for: what it's used for, when it renews, and whether you'd consider alternatives. About 30–60 minutes for most companies.
B5: How to fill it in
B6: 1. Company Profile | C6: Your company, contacts, how you buy software, and any AWS or Microsoft cloud commitments.
B7: 2. ISV Inventory | C7: One row per product per contract. Pick the product from the dropdown, or type it if it isn't listed. Fill the yellow columns; grey columns calculate themselves.
B8: 3. Discovery Questions | C8: Answer what you can. We'll cover the rest in the discovery session.
B9: Then check | C9: Renewal Calendar lists every renewal in date order. Summary shows totals, renewals by month, overlapping tools, and how open you are to alternatives.
B10: Legend
B11: Yellow cell | C11: You fill this in.
B12: Grey cell | C12: Calculated or looked up from the catalog. Don't type here.
B13: * in a header | C13: Required: product, primary use case, renewal date, and whether you're open to alternatives.
B14: Red / amber highlight | C14: Renewal is past due or within 90 days; auto-renew notice deadline is within 45 days; fewer than 75% of licenses are in use.
B15: Tips
B16: Cost | C16: Give either the annual cost, or price per user per month plus number of licenses. Use the currency you pay in (assumed USD).
B17: Dates | C17: Type dates as YYYY-MM-DD (2027-01-31). If the renewal date is unknown, put your best estimate and say so in Notes.
B18: Open to alternatives? | C18: Be candid. “Maybe – depends on price” is useful: it tells us to benchmark before the renewal.
B19: Not in the list? | C19: Type the name anyway. The In catalog? column will say “No – will be reviewed”, and we'll add it.
B20: Example row | C20: Row 6 of ISV Inventory is a filled-in example. Replace it or delete its contents.
B21: What happens next
C22: We review the workbook, match each product to our catalog of 157 ISVs, and send back a renewal plan: notice deadlines to calendar, licenses to right-size, overlapping tools, alternatives worth a look, and which renewals could be bought through AWS or Microsoft Marketplace against your cloud commitment.
B23: Confidentiality | C23: This workbook contains commercial terms. Share it only with the people who need it.
B25: Catalog version: 157 products. Marketplace status as of October 2026; listings change, so treat it as a guide.

Sheet Company Profile
B2: Company Profile
B3: Fill the yellow cells. * = required.
B5: Company
B6: Company legal name *
B7: Other names used (comma-separated)
B8: Industry *
B9: Employees *
B10: Headquarters country
B11: Fiscal year ends (month)
B12: People
B13: Executive sponsor *
B14: Sponsor title
... B42: Consultant / account lead

Sheet ISV Inventory
A1: ISV Inventory
A2: One row per product per contract. Yellow = you fill in · Grey = calculated · * = required. Hover a header for help.
A3: ="Products listed: "&COUNTA(B6:B255)&" · Annual spend: "&TEXT(SUM(R6:R255),"$#,##0") -> Products listed: 1 · Annual spend: $58,500
A4: Product | E4: Ownership & use case | M4: Licenses & cost | U4: Contract & renewal | AE4: Satisfaction & alternatives | AN4: From the catalog (automatic)
A5: # | B5: Product / application * | C5: Edition / SKU / plan | D5: Vendor | E5: Department / business unit | F5: Business owner | G5: Technical owner / admin | H5: Primary use case * | I5: Other use cases | J5: Business criticality | K5: Key integrations | L5: Data sensitivity | M5: Licenses / seats | N5: Active users (last 90 days) | O5: Utilization | P5: Price per user / month ($) | Q5: Annual cost ($) | R5: Annual spend ($) | S5: Billing frequency | T5: Purchased via | U5: Contract start date | V5: Renewal / contract end date * | W5: Term (months) | X5: Auto-renews? | Y5: Notice period (days) | Z5: Notice deadline | AA5: Days to renewal | AB5: Renewal window | AC5: Price increase cap at renewal (%) | AD5: Can terminate early? | AE5: Satisfaction (1–5) | AF5: Pain points / gaps | AG5: Open to alternatives after renewal? * | AH5: Alternatives being considered | AI5: Main reason to switch | AJ5: Switching barriers | AK5: Desired outcome at renewal | AL5: Decision maker | AM5: Notes | AN5: Catalog product | AO5: In catalog? | AP5: Catalog vendor | AQ5: Category | AR5: AWS Marketplace | AS5: Microsoft Marketplace | AT5: Catalog alternatives | AU5: sort key
A6: =IF(B6="","",ROW()-5) -> 1 | B6: Okta Workforce Identity | C6: SSO + MFA | E6: IT | F6: IT Director | G6: Identity team | H6: Single sign-on and MFA for all employees and contractors | I6: Lifecycle provisioning to HR system | J6: Mission-critical | K6: Workday, Google Workspace, AWS | L6: Confidential | M6: 650 | N6: 612 | O6: =IF(OR(M6="",N6="",M6=0),"",N6/M6) -> 0.94153846 | Q6: 58500 | R6: =IF(Q6<>"",Q6,IF(AND(P6<>"",M6<>""),P6*12*M6,"")) -> 58500 | S6: Annual upfront | T6: Direct | U6: 45982 | V6: 46346 | W6: 12 | X6: Yes | Y6: 30 | Z6: =IF(OR(V6="",Y6=""),"",V6-Y6) -> 46316 | AA6: =IF(V6="","",V6-TODAY()) -> 36 | AB6: =IF(V6="","",IF(AA6<0,"Past due",IF(AA6<=90,"0–90 days",IF(AA6<=180,"91–180 days",IF(AA6<=365,"181–365 days","Over a year"))))) -> 0–90 days | AC6: 0.05 | AD6: No | AE6: 4 | AF6: Price went up 7% last year | AG6: Maybe – depends on price | AH6: Microsoft Entra ID P1 | AI6: Cost | AJ6: 120 app integrations to re-point | AK6: Renegotiate price | AL6: CFO | AM6: EXAMPLE ROW: replace or delete | AN6: =IF(B6="","",IFERROR(INDEX(Lookup!$B$2:$B$3000,MATCH(TRIM(B6),Lookup!$A$2:$A$3000,0)),"")) -> Okta Workforce Identity | AO6: =IF(B6="","",IF(AN6="","No – will be reviewed","Yes")) -> Yes | AP6: =IF(AN6="","",IFERROR(INDEX(Catalog!$B$5:$B$400,MATCH(AN6,Catalog!$A$5:$A$400,0)),"")) -> Okta | AQ6: =IF(AN6="","",IFERROR(INDEX(Catalog!$C$5:$C$400,MATCH(AN6,Catalog!$A$5:$A$400,0)),"")) -> Identity | AR6: =IF(AN6="","",IFERROR(INDEX(Catalog!$D$5:$D$400,MATCH(AN6,Catalog!$A$5:$A$400,0)),"")) -> Listed | AS6: =IF(AN6="","",IFERROR(INDEX(Catalog!$E$5:$E$400,MATCH(AN6,Catalog!$A$5:$A$400,0)),"")) -> Add-in only | AT6: =IF(AN6="","",IFERROR(INDEX(Catalog!$F$5:$F$400,MATCH(AN6,Catalog!$A$5:$A$400,0)),"")) -> Microsoft Entra ID P1, Ping Identity, JumpCloud | AU6: =IF(AND(B6<>"",ISNUMBER(V6)),V6+ROW()/100000,"") -> 46346
A7: =IF(B7="","",ROW()-5) | O7: =IF(OR(M7="",N7="",M7=0),"",N7/M7) | R7: =IF(Q7<>"",Q7,IF(AND(P7<>"",M7<>""),P7*12*M7,"")) | Z7: =IF(OR(V7="",Y7=""),"",V7-Y7) | AA7: =IF(V7="","",V7-TODAY()) | AB7: =IF(V7="","",IF(AA7<0,"Past due",IF(AA7<=90,"0–90 days",IF(AA7<=180,"91–180 days",IF(AA7<=365,"181–365 days","Over a year"))))) | AN7: =IF(B7="","",IFERROR(INDEX(Lookup!$B$2:$B$3000,MATCH(TRIM(B7),Lookup!$A$2:$A$3000,0)),"")) | AO7: =IF(B7="","",IF(AN7="","No – will be reviewed","Yes")) | AP7: =IF(AN7="","",IFERROR(INDEX(Catalog!$B$5:$B$400,MATCH(AN7,Catalog!$A$5:$A$400,0)),"")) | AQ7: =IF(AN7="","",IFERROR(INDEX(Catalog!$C$5:$C$400,MATCH(AN7,Catalog!$A$5:$A$400,0)),"")) | AR7: =IF(AN7="","",IFERROR(INDEX(Catalog!$D$5:$D$400,MATCH(AN7,Catalog!$A$5:$A$400,0)),"")) | AS7: =IF(AN7="","",IFERROR(INDEX(Catalog!$E$5:$E$400,MATCH(AN7,Catalog!$A$5:$A$400,0)),"")) | AT7: =IF(AN7="","",IFERROR(INDEX(Catalog!$F$5:$F$400,MATCH(AN7,Catalog!$A$5:$A$400,0)),"")) | AU7: =IF(AND(B7<>"",ISNUMBER(V7)),V7+ROW()/100000,"")
A8: =IF(B8="","",ROW()-5) | O8: =IF(OR(M8="",N8="",M8=0),"",N8/M8) | R8: =IF(Q8<>"",Q8,IF(AND(P8<>"",M8<>""),P8*12*M8,"")) | Z8: =IF(OR(V8="",Y8=""),"",V8-Y8) | AA8: =IF(V8="","",V8-TODAY()) | AB8: =IF(V8="","",IF(AA8<0,"Past due",IF(AA8<=90,"0–90 days",IF(AA8<=180,"91–180 days",IF(AA8<=365,"181–365 days","Over a year"))))) | AN8: =IF(B8="","",IFERROR(INDEX(Lookup!$B$2:$B$3000,MATCH(TRIM(B8),Lookup!$A$2:$A$3000,0)),"")) | AO8: =IF(B8="","",IF(AN8="","No – will be reviewed","Yes")) | AP8: =IF(AN8="","",IFERROR(INDEX(Catalog!$B$5:$B$400,MATCH(AN8,Catalog!$A$5:$A$400,0)),"")) | AQ8: =IF(AN8="","",IFERROR(INDEX(Catalog!$C$5:$C$400,MATCH(AN8,Catalog!$A$5:$A$400,0)),"")) | AR8: =IF(AN8="","",IFERROR(INDEX(Catalog!$D$5:$D$400,MATCH(AN8,Catalog!$A$5:$A$400,0)),"")) | AS8: =IF(AN8="","",IFERROR(INDEX(Catalog!$E$5:$E$400,MATCH(AN8,Catalog!$A$5:$A$400,0)),"")) | AT8: =IF(AN8="","",IFERROR(INDEX(Catalog!$F$5:$F$400,MATCH(AN8,Catalog!$A$5:$A$400,0)),"")) | AU8: =IF(AND(B8<>"",ISNUMBER(V8)),V8+ROW()/100000,"")
A9: =IF(B9="","",ROW()-5) | O9: =IF(OR(M9="",N9="",M9=0),"",N9/M9) | R9: =IF(Q9<>"",Q9,IF(AND(P9<>"",M9<>""),P9*12*M9,"")) | Z9: =IF(OR(V9="",Y9=""),"",V9-Y9) | AA9: =IF(V9="","",V9-TODAY()) | AB9: =IF(V9="","",IF(AA9<0,"Past due",IF(AA9<=90,"0–90 days",IF(AA9<=180,"91–180 days",IF(AA9<=365,"181–365 days","Over a year"))))) | AN9: =IF(B9="","",IFERROR(INDEX(Lookup!$B$2:$B$3000,MATCH(TRIM(B9),Lookup!$A$2:$A$3000,0)),"")) | AO9: =IF(B9="","",IF(AN9="","No – will be reviewed","Yes")) | AP9: =IF(AN9="","",IFERROR(INDEX(Catalog!$B$5:$B$400,MATCH(AN9,Catalog!$A$5:$A$400,0)),"")) | AQ9: =IF(AN9="","",IFERROR(INDEX(Catalog!$C$5:$C$400,MATCH(AN9,Catalog!$A$5:$A$400,0)),"")) | AR9: =IF(AN9="","",IFERROR(INDEX(Catalog!$D$5:$D$400,MATCH(AN9,Catalog!$A$5:$A$400,0)),"")) | AS9: =IF(AN9="","",IFERROR(INDEX(Catalog!$E$5:$E$400,MATCH(AN9,Catalog!$A$5:$A$400,0)),"")) | AT9: =IF(AN9="","",IFERROR(INDEX(Catalog!$F$5:$F$400,MATCH(AN9,Catalog!$A$5:$A$400,0)),"")) | AU9: =IF(AND(B9<>"",ISNUMBER(V9)),V9+ROW()/100000,"")
A10: =IF(B10="","",ROW()-5) | O10: =IF(OR(M10="",N10="",M10=0),"",N10/M10) | R10: =IF(Q10<>"",Q10,IF(AND(P10<>"",M10<>""),P10*12*M10,"")) | Z10: =IF(OR(V10="",Y10=""),"",V10-Y10) | AA10: =IF(V10="","",V10-TODAY()) | AB10: =IF(V10="","",IF(AA10<0,"Past due",IF(AA10<=90,"0–90 days",IF(AA10<=180,"91–180 days",IF(AA10<=365,"181–365 days","Over a year"))))) | AN10: =IF(B10="","",IFERROR(INDEX(Lookup!$B$2:$B$3000,MATCH(TRIM(B10),Lookup!$A$2:$A$3000,0)),"")) | AO10: =IF(B10="","",IF(AN10="","No – will be reviewed","Yes")) | AP10: =IF(AN10="","",IFERROR(INDEX(Catalog!$B$5:$B$400,MATCH(AN10,Catalog!$A$5:$A$400,0)),"")) | AQ10: =IF(AN10="","",IFERROR(INDEX(Catalog!$C$5:$C$400,MATCH(AN10,Catalog!$A$5:$A$400,0)),"")) | AR10: =IF(AN10="","",IFERROR(INDEX(Catalog!$D$5:$D$400,MATCH(AN10,Catalog!$A$5:$A$400,0)),"")) | AS10: =IF(AN10="","",IFERROR(INDEX(Catalog!$E$5:$E$400,MATCH(AN10,Catalog!$A$5:$A$400,0)),"")) | AT10: =IF(AN10="","",IFERROR(INDEX(Catalog!$F$5:$F$400,MATCH(AN10,Catalog!$A$5:$A$400,0)),"")) | AU10: =IF(AND(B10<>"",ISNUMBER(V10)),V10+ROW()/100000,"")
A11: =IF(B11="","",ROW()-5) | O11: =IF(OR(M11="",N11="",M11=0),"",N11/M11) | R11: =IF(Q11<>"",Q11,IF(AND(P11<>"",M11<>""),P11*12*M11,"")) | Z11: =IF(OR(V11="",Y11=""),"",V11-Y11) | AA11: =IF(V11="","",V11-TODAY()) | AB11: =IF(V11="","",IF(AA11<0,"Past due",IF(AA11<=90,"0–90 days",IF(AA11<=180,"91–180 days",IF(AA11<=365,"181–365 days","Over a year"))))) | AN11: =IF(B11="","",IFERROR(INDEX(Lookup!$B$2:$B$3000,MATCH(TRIM(B11),Lookup!$A$2:$A$3000,0)),"")) | AO11: =IF(B11="","",IF(AN11="","No – will be reviewed","Yes")) | AP11: =IF(AN11="","",IFERROR(INDEX(Catalog!$B$5:$B$400,MATCH(AN11,Catalog!$A$5:$A$400,0)),"")) | AQ11: =IF(AN11="","",IFERROR(INDEX(Catalog!$C$5:$C$400,MATCH(AN11,Catalog!$A$5:$A$400,0)),"")) | AR11: =IF(AN11="","",IFERROR(INDEX(Catalog!$D$5:$D$400,MATCH(AN11,Catalog!$A$5:$A$400,0)),"")) | AS11: =IF(AN11="","",IFERROR(INDEX(Catalog!$E$5:$E$400,MATCH(AN11,Catalog!$A$5:$A$400,0)),"")) | AT11: =IF(AN11="","",IFERROR(INDEX(Catalog!$F$5:$F$400,MATCH(AN11,Catalog!$A$5:$A$400,0)),"")) | AU11: =IF(AND(B11<>"",ISNUMBER(V11)),V11+ROW()/100000,"")
A12: =IF(B12="","",ROW()-5) | O12: =IF(OR(M12="",N12="",M12=0),"",N12/M12) | R12: =IF(Q12<>"",Q12,IF(AND(P12<>"",M12<>""),P12*12*M12,"")) | Z12: =IF(OR(V12="",Y12=""),"",V12-Y12) | AA12: =IF(V12="","",V12-TODAY()) | AB12: =IF(V12="","",IF(AA12<0,"Past due",IF(AA12<=90,"0–90 days",IF(AA12<=180,"91–180 days",IF(AA12<=365,"181–365 days","Over a year"))))) | AN12: =IF(B12="","",IFERROR(INDEX(Lookup!$B$2:$B$3000,MATCH(TRIM(B12),Lookup!$A$2:$A$3000,0)),"")) | AO12: =IF(B12="","",IF(AN12="","No – will be reviewed","Yes")) | AP12: =IF(AN12="","",IFERROR(INDEX(Catalog!$B$5:$B$400,MATCH(AN12,Catalog!$A$5:$A$400,0)),"")) | AQ12: =IF(AN12="","",IFERROR(INDEX(Catalog!$C$5:$C$400,MATCH(AN12,Catalog!$A$5:$A$400,0)),"")) | AR12: =IF(AN12="","",IFERROR(INDEX(Catalog!$D$5:$D$400,MATCH(AN12,Catalog!$A$5:$A$400,0)),"")) | AS12: =IF(AN12="","",IFERROR(INDEX(Catalog!$E$5:$E$400,MATCH(AN12,Catalog!$A$5:$A$400,0)),"")) | AT12: =IF(AN12="","",IFERROR(INDEX(Catalog!$F$5:$F$400,MATCH(AN12,Catalog!$A$5:$A$400,0)),"")) | AU12: =IF(AND(B12<>"",ISNUMBER(V12)),V12+ROW()/100000,"")
A13: =IF(B13="","",ROW()-5) | O13: =IF(OR(M13="",N13="",M13=0),"",N13/M13) | R13: =IF(Q13<>"",Q13,IF(AND(P13<>"",M13<>""),P13*12*M13,"")) | Z13: =IF(OR(V13="",Y13=""),"",V13-Y13) | AA13: =IF(V13="","",V13-TODAY()) | AB13: =IF(V13="","",IF(AA13<0,"Past due",IF(AA13<=90,"0–90 days",IF(AA13<=180,"91–180 days",IF(AA13<=365,"181–365 days","Over a year"))))) | AN13: =IF(B13="","",IFERROR(INDEX(Lookup!$B$2:$B$3000,MATCH(TRIM(B13),Lookup!$A$2:$A$3000,0)),"")) | AO13: =IF(B13="","",IF(AN13="","No – will be reviewed","Yes")) | AP13: =IF(AN13="","",IFERROR(INDEX(Catalog!$B$5:$B$400,MATCH(AN13,Catalog!$A$5:$A$400,0)),"")) | AQ13: =IF(AN13="","",IFERROR(INDEX(Catalog!$C$5:$C$400,MATCH(AN13,Catalog!$A$5:$A$400,0)),"")) | AR13: =IF(AN13="","",IFERROR(INDEX(Catalog!$D$5:$D$400,MATCH(AN13,Catalog!$A$5:$A$400,0)),"")) | AS13: =IF(AN13="","",IFERROR(INDEX(Catalog!$E$5:$E$400,MATCH(AN13,Catalog!$A$5:$A$400,0)),"")) | AT13: =IF(AN13="","",IFERROR(INDEX(Catalog!$F$5:$F$400,MATCH(AN13,Catalog!$A$5:$A$400,0)),"")) | AU13: =IF(AND(B13<>"",ISNUMBER(V13)),V13+ROW()/100000,"")
A14: =IF(B14="","",ROW()-5) | O14: =IF(OR(M14="",N14="",M14=0),"",N14/M14) | R14: =IF(Q14<>"",Q14,IF(AND(P14<>"",M14<>""),P14*12*M14,"")) | Z14: =IF(OR(V14="",Y14=""),"",V14-Y14) | AA14: =IF(V14="","",V14-TODAY()) | AB14: =IF(V14="","",IF(AA14<0,"Past due",IF(AA14<=90,"0–90 days",IF(AA14<=180,"91–180 days",IF(AA14<=365,"181–365 days","Over a year"))))) | AN14: =IF(B14="","",IFERROR(INDEX(Lookup!$B$2:$B$3000,MATCH(TRIM(B14),Lookup!$A$2:$A$3000,0)),"")) | AO14: =IF(B14="","",IF(AN14="","No – will be reviewed","Yes")) | AP14: =IF(AN14="","",IFERROR(INDEX(Catalog!$B$5:$B$400,MATCH(AN14,Catalog!$A$5:$A$400,0)),"")) | AQ14: =IF(AN14="","",IFERROR(INDEX(Catalog!$C$5:$C$400,MATCH(AN14,Catalog!$A$5:$A$400,0)),"")) | AR14: =IF(AN14="","",IFERROR(INDEX(Catalog!$D$5:$D$400,MATCH(AN14,Catalog!$A$5:$A$400,0)),"")) | AS14: =IF(AN14="","",IFERROR(INDEX(Catalog!$E$5:$E$400,MATCH(AN14,Catalog!$A$5:$A$400,0)),"")) | AT14: =IF(AN14="","",IFERROR(INDEX(Catalog!$F$5:$F$400,MATCH(AN14,Catalog!$A$5:$A$400,0)),"")) | AU14: =IF(AND(B14<>"",ISNUMBER(V14)),V14+ROW()/100000,"")
A15: =IF(B15="","",ROW()-5) | O15: =IF(OR(M15="",N15="",M15=0),"",N15/M15) | R15: =IF(Q15<>"",Q15,IF(AND(P15<>"",M15<>""),P15*12*M15,"")) | Z15: =IF(OR(V15="",Y15=""),"",V15-Y15) | AA15: =IF(V15="","",V15-TODAY()) | AB15: =IF(V15="","",IF(AA15<0,"Past due",IF(AA15<=90,"0–90 days",IF(AA15<=180,"91–180 days",IF(AA15<=365,"181–365 days","Over a year"))))) | AN15: =IF(B15="","",IFERROR(INDEX(Lookup!$B$2:$B$3000,MATCH(TRIM(B15),Lookup!$A$2:$A$3000,0)),"")) | AO15: =IF(B15="","",IF(AN15="","No – will be reviewed","Yes")) | AP15: =IF(AN15="","",IFERROR(INDEX(Catalog!$B$5:$B$400,MATCH(AN15,Catalog!$A$5:$A$400,0)),"")) | AQ15: =IF(AN15="","",IFERROR(INDEX(Catalog!$C$5:$C$400,MATCH(AN15,Catalog!$A$5:$A$400,0)),"")) | AR15: =IF(AN15="","",IFERROR(INDEX(Catalog!$D$5:$D$400,MATCH(AN15,Catalog!$A$5:$A$400,0)),"")) | AS15: =IF(AN15="","",IFERROR(INDEX(Catalog!$E$5:$E$400,MATCH(AN15,Catalog!$A$5:$A$400,0)),"")) | AT15: =IF(AN15="","",IFERROR(INDEX(Catalog!$F$5:$F$400,MATCH(AN15,Catalog!$A$5:$A$400,0)),"")) | AU15: =IF(AND(B15<>"",ISNUMBER(V15)),V15+ROW()/100000,"")
A16: =IF(B16="","",ROW()-5) | O16: =IF(OR(M16="",N16="",M16=0),"",N16/M16) | R16: =IF(Q16<>"",Q16,IF(AND(P16<>"",M16<>""),P16*12*M16,"")) | Z16: =IF(OR(V16="",Y16=""),"",V16-Y16) | AA16: =IF(V16="","",V16-TODAY()) | AB16: =IF(V16="","",IF(AA16<0,"Past due",IF(AA16<=90,"0–90 days",IF(AA16<=180,"91–180 days",IF(AA16<=365,"181–365 days","Over a year"))))) | AN16: =IF(B16="","",IFERROR(INDEX(Lookup!$B$2:$B$3000,MATCH(TRIM(B16),Lookup!$A$2:$A$3000,0)),"")) | AO16: =IF(B16="","",IF(AN16="","No – will be reviewed","Yes")) | AP16: =IF(AN16="","",IFERROR(INDEX(Catalog!$B$5:$B$400,MATCH(AN16,Catalog!$A$5:$A$400,0)),"")) | AQ16: =IF(AN16="","",IFERROR(INDEX(Catalog!$C$5:$C$400,MATCH(AN16,Catalog!$A$5:$A$400,0)),"")) | AR16: =IF(AN16="","",IFERROR(INDEX(Catalog!$D$5:$D$400,MATCH(AN16,Catalog!$A$5:$A$400,0)),"")) | AS16: =IF(AN16="","",IFERROR(INDEX(Catalog!$E$5:$E$400,MATCH(AN16,Catalog!$A$5:$A$400,0)),"")) | AT16: =IF(AN16="","",IFERROR(INDEX(Catalog!$F$5:$F$400,MATCH(AN16,Catalog!$A$5:$A$400,0)),"")) | AU16: =IF(AND(B16<>"",ISNUMBER(V16)),V16+ROW()/100000,"")
A17: =IF(B17="","",ROW()-5) | O17: =IF(OR(M17="",N17="",M17=0),"",N17/M17) | R17: =IF(Q17<>"",Q17,IF(AND(P17<>"",M17<>""),P17*12*M17,"")) | Z17: =IF(OR(V17="",Y17=""),"",V17-Y17) | AA17: =IF(V17="","",V17-TODAY()) | AB17: =IF(V17="","",IF(AA17<0,"Past due",IF(AA17<=90,"0–90 days",IF(AA17<=180,"91–180 days",IF(AA17<=365,"181–365 days","Over a year"))))) | AN17: =IF(B17="","",IFERROR(INDEX(Lookup!$B$2:$B$3000,MATCH(TRIM(B17),Lookup!$A$2:$A$3000,0)),"")) | AO17: =IF(B17="","",IF(AN17="","No – will be reviewed","Yes")) | AP17: =IF(AN17="","",IFERROR(INDEX(Catalog!$B$5:$B$400,MATCH(AN17,Catalog!$A$5:$A$400,0)),"")) | AQ17: =IF(AN17="","",IFERROR(INDEX(Catalog!$C$5:$C$400,MATCH(AN17,Catalog!$A$5:$A$400,0)),"")) | AR17: =IF(AN17="","",IFERROR(INDEX(Catalog!$D$5:$D$400,MATCH(AN17,Catalog!$A$5:$A$400,0)),"")) | AS17: =IF(AN17="","",IFERROR(INDEX(Catalog!$E$5:$E$400,MATCH(AN17,Catalog!$A$5:$A$400,0)),"")) | AT17: =IF(AN17="","",IFERROR(INDEX(Catalog!$F$5:$F$400,MATCH(AN17,Catalog!$A$5:$A$400,0)),"")) | AU17: =IF(AND(B17<>"",ISNUMBER(V17)),V17+ROW()/100000,"")
A18: =IF(B18="","",ROW()-5) | O18: =IF(OR(M18="",N18="",M18=0),"",N18/M18) | R18: =IF(Q18<>"",Q18,IF(AND(P18<>"",M18<>""),P18*12*M18,"")) | Z18: =IF(OR(V18="",Y18=""),"",V18-Y18) | AA18: =IF(V18="","",V18-TODAY()) | AB18: =IF(V18="","",IF(AA18<0,"Past due",IF(AA18<=90,"0–90 days",IF(AA18<=180,"91–180 days",IF(AA18<=365,"181–365 days","Over a year"))))) | AN18: =IF(B18="","",IFERROR(INDEX(Lookup!$B$2:$B$3000,MATCH(TRIM(B18),Lookup!$A$2:$A$3000,0)),"")) | AO18: =IF(B18="","",IF(AN18="","No – will be reviewed","Yes")) | AP18: =IF(AN18="","",IFERROR(INDEX(Catalog!$B$5:$B$400,MATCH(AN18,Catalog!$A$5:$A$400,0)),"")) | AQ18: =IF(AN18="","",IFERROR(INDEX(Catalog!$C$5:$C$400,MATCH(AN18,Catalog!$A$5:$A$400,0)),"")) | AR18: =IF(AN18="","",IFERROR(INDEX(Catalog!$D$5:$D$400,MATCH(AN18,Catalog!$A$5:$A$400,0)),"")) | AS18: =IF(AN18="","",IFERROR(INDEX(Catalog!$E$5:$E$400,MATCH(AN18,Catalog!$A$5:$A$400,0)),"")) | AT18: =IF(AN18="","",IFERROR(INDEX(Catalog!$F$5:$F$400,MATCH(AN18,Catalog!$A$5:$A$400,0)),"")) | AU18: =IF(AND(B18<>"",ISNUMBER(V18)),V18+ROW()/100000,"")
... A255: =IF(B255="","",ROW()-5) | O255: =IF(OR(M255="",N255="",M255=0),"",N255/M255) | R255: =IF(Q255<>"",Q255,IF(AND(P255<>"",M255<>""),P255*12*M255,"")) | Z255: =IF(OR(V255="",Y255=""),"",V255-Y255) | AA255: =IF(V255="","",V255-TODAY()) | AB255: =IF(V255="","",IF(AA255<0,"Past due",IF(AA255<=90,"0–90 days",IF(AA255<=180,"91–180 days",IF(AA255<=365,"181–365 days","Over a year"))))) | AN255: =IF(B255="","",IFERROR(INDEX(Lookup!$B$2:$B$3000,MATCH(TRIM(B255),Lookup!$A$2:$A$3000,0)),"")) | AO255: =IF(B255="","",IF(AN255="","No – will be reviewed","Yes")) | AP255: =IF(AN255="","",IFERROR(INDEX(Catalog!$B$5:$B$400,MATCH(AN255,Catalog!$A$5:$A$400,0)),"")) | AQ255: =IF(AN255="","",IFERROR(INDEX(Catalog!$C$5:$C$400,MATCH(AN255,Catalog!$A$5:$A$400,0)),"")) | AR255: =IF(AN255="","",IFERROR(INDEX(Catalog!$D$5:$D$400,MATCH(AN255,Catalog!$A$5:$A$400,0)),"")) | AS255: =IF(AN255="","",IFERROR(INDEX(Catalog!$E$5:$E$400,MATCH(AN255,Catalog!$A$5:$A$400,0)),"")) | AT255: =IF(AN255="","",IFERROR(INDEX(Catalog!$F$5:$F$400,MATCH(AN255,Catalog!$A$5:$A$400,0)),"")) | AU255: =IF(AND(B255<>"",ISNUMBER(V255)),V255+ROW()/100000,"")

Sheet Renewal Calendar
A1: Renewal Calendar
A2: Every product with a renewal date, soonest first. Calculated from ISV Inventory; don't type here.
A4: # | B4: Renewal date | C4: Days | D4: Window | E4: Product | F4: Business owner | G4: Annual spend ($) | H4: Auto-renews? | I4: Notice deadline | J4: Open to alternatives? | K4: Desired outcome | L4: AWS Marketplace | M4: Microsoft Marketplace
A5: =IF(COUNT('ISV Inventory'!$AU$6:$AU$255)<1,"",1) -> 1 | B5: =IF($A5="","",IFERROR(INDEX('ISV Inventory'!$V$6:$V$255,MATCH(SMALL('ISV Inventory'!$AU$6:$AU$255,$A5),'ISV Inventory'!$AU$6:$AU$255,0)),"")) -> 46346 | C5: =IF($A5="","",IFERROR(INDEX('ISV Inventory'!$AA$6:$AA$255,MATCH(SMALL('ISV Inventory'!$AU$6:$AU$255,$A5),'ISV Inventory'!$AU$6:$AU$255,0)),"")) -> 36 | D5: =IF($A5="","",IFERROR(INDEX('ISV Inventory'!$AB$6:$AB$255,MATCH(SMALL('ISV Inventory'!$AU$6:$AU$255,$A5),'ISV Inventory'!$AU$6:$AU$255,0))&"","")) -> 0–90 days | E5: =IF($A5="","",IFERROR(INDEX('ISV Inventory'!$B$6:$B$255,MATCH(SMALL('ISV Inventory'!$AU$6:$AU$255,$A5),'ISV Inventory'!$AU$6:$AU$255,0))&"","")) -> Okta Workforce Identity | F5: =IF($A5="","",IFERROR(INDEX('ISV Inventory'!$F$6:$F$255,MATCH(SMALL('ISV Inventory'!$AU$6:$AU$255,$A5),'ISV Inventory'!$AU$6:$AU$255,0))&"","")) -> IT Director | G5: =IF($A5="","",IFERROR(INDEX('ISV Inventory'!$R$6:$R$255,MATCH(SMALL('ISV Inventory'!$AU$6:$AU$255,$A5),'ISV Inventory'!$AU$6:$AU$255,0)),"")) -> 58500 | H5: =IF($A5="","",IFERROR(INDEX('ISV Inventory'!$X$6:$X$255,MATCH(SMALL('ISV Inventory'!$AU$6:$AU$255,$A5),'ISV Inventory'!$AU$6:$AU$255,0))&"","")) -> Yes | I5: =IF($A5="","",IFERROR(INDEX('ISV Inventory'!$Z$6:$Z$255,MATCH(SMALL('ISV Inventory'!$AU$6:$AU$255,$A5),'ISV Inventory'!$AU$6:$AU$255,0)),"")) -> 46316 | J5: =IF($A5="","",IFERROR(INDEX('ISV Inventory'!$AG$6:$AG$255,MATCH(SMALL('ISV Inventory'!$AU$6:$AU$255,$A5),'ISV Inventory'!$AU$6:$AU$255,0))&"","")) -> Maybe – depends on price | K5: =IF($A5="","",IFERROR(INDEX('ISV Inventory'!$AK$6:$AK$255,MATCH(SMALL('ISV Inventory'!$AU$6:$AU$255,$A5),'ISV Inventory'!$AU$6:$AU$255,0))&"","")) -> Renegotiate price | L5: =IF($A5="","",IFERROR(INDEX('ISV Inventory'!$AR$6:$AR$255,MATCH(SMALL('ISV Inventory'!$AU$6:$AU$255,$A5),'ISV Inventory'!$AU$6:$AU$255,0))&"","")) -> Listed | M5: =IF($A5="","",IFERROR(INDEX('ISV Inventory'!$AS$6:$AS$255,MATCH(SMALL('ISV Inventory'!$AU$6:$AU$255,$A5),'ISV Inventory'!$AU$6:$AU$255,0))&"","")) -> Add-in only
A6: =IF(COUNT('ISV Inventory'!$AU$6:$AU$255)<2,"",2) | B6: =IF($A6="","",IFERROR(INDEX('ISV Inventory'!$V$6:$V$255,MATCH(SMALL('ISV Inventory'!$AU$6:$AU$255,$A6),'ISV Inventory'!$AU$6:$AU$255,0)),"")) | C6: =IF($A6="","",IFERROR(INDEX('ISV Inventory'!$AA$6:$AA$255,MATCH(SMALL('ISV Inventory'!$AU$6:$AU$255,$A6),'ISV Inventory'!$AU$6:$AU$255,0)),"")) | D6: =IF($A6="","",IFERROR(INDEX('ISV Inventory'!$AB$6:$AB$255,MATCH(SMALL('ISV Inventory'!$AU$6:$AU$255,$A6),'ISV Inventory'!$AU$6:$AU$255,0))&"","")) | E6: =IF($A6="","",IFERROR(INDEX('ISV Inventory'!$B$6:$B$255,MATCH(SMALL('ISV Inventory'!$AU$6:$AU$255,$A6),'ISV Inventory'!$AU$6:$AU$255,0))&"","")) | F6: =IF($A6="","",IFERROR(INDEX('ISV Inventory'!$F$6:$F$255,MATCH(SMALL('ISV Inventory'!$AU$6:$AU$255,$A6),'ISV Inventory'!$AU$6:$AU$255,0))&"","")) | G6: =IF($A6="","",IFERROR(INDEX('ISV Inventory'!$R$6:$R$255,MATCH(SMALL('ISV Inventory'!$AU$6:$AU$255,$A6),'ISV Inventory'!$AU$6:$AU$255,0)),"")) | H6: =IF($A6="","",IFERROR(INDEX('ISV Inventory'!$X$6:$X$255,MATCH(SMALL('ISV Inventory'!$AU$6:$AU$255,$A6),'ISV Inventory'!$AU$6:$AU$255,0))&"","")) | I6: =IF($A6="","",IFERROR(INDEX('ISV Inventory'!$Z$6:$Z$255,MATCH(SMALL('ISV Inventory'!$AU$6:$AU$255,$A6),'ISV Inventory'!$AU$6:$AU$255,0)),"")) | J6: =IF($A6="","",IFERROR(INDEX('ISV Inventory'!$AG$6:$AG$255,MATCH(SMALL('ISV Inventory'!$AU$6:$AU$255,$A6),'ISV Inventory'!$AU$6:$AU$255,0))&"","")) | K6: =IF($A6="","",IFERROR(INDEX('ISV Inventory'!$AK$6:$AK$255,MATCH(SMALL('ISV Inventory'!$AU$6:$AU$255,$A6),'ISV Inventory'!$AU$6:$AU$255,0))&"","")) | L6: =IF($A6="","",IFERROR(INDEX('ISV Inventory'!$AR$6:$AR$255,MATCH(SMALL('ISV Inventory'!$AU$6:$AU$255,$A6),'ISV Inventory'!$AU$6:$AU$255,0))&"","")) | M6: =IF($A6="","",IFERROR(INDEX('ISV Inventory'!$AS$6:$AS$255,MATCH(SMALL('ISV Inventory'!$AU$6:$AU$255,$A6),'ISV Inventory'!$AU$6:$AU$255,0))&"",""))
A7: =IF(COUNT('ISV Inventory'!$AU$6:$AU$255)<3,"",3) | B7: =IF($A7="","",IFERROR(INDEX('ISV Inventory'!$V$6:$V$255,MATCH(SMALL('ISV Inventory'!$AU$6:$AU$255,$A7),'ISV Inventory'!$AU$6:$AU$255,0)),"")) | C7: =IF($A7="","",IFERROR(INDEX('ISV Inventory'!$AA$6:$AA$255,MATCH(SMALL('ISV Inventory'!$AU$6:$AU$255,$A7),'ISV Inventory'!$AU$6:$AU$255,0)),"")) | D7: =IF($A7="","",IFERROR(INDEX('ISV Inventory'!$AB$6:$AB$255,MATCH(SMALL('ISV Inventory'!$AU$6:$AU$255,$A7),'ISV Inventory'!$AU$6:$AU$255,0))&"","")) | E7: =IF($A7="","",IFERROR(INDEX('ISV Inventory'!$B$6:$B$255,MATCH(SMALL('ISV Inventory'!$AU$6:$AU$255,$A7),'ISV Inventory'!$AU$6:$AU$255,0))&"","")) | F7: =IF($A7="","",IFERROR(INDEX('ISV Inventory'!$F$6:$F$255,MATCH(SMALL('ISV Inventory'!$AU$6:$AU$255,$A7),'ISV Inventory'!$AU$6:$AU$255,0))&"","")) | G7: =IF($A7="","",IFERROR(INDEX('ISV Inventory'!$R$6:$R$255,MATCH(SMALL('ISV Inventory'!$AU$6:$AU$255,$A7),'ISV Inventory'!$AU$6:$AU$255,0)),"")) | H7: =IF($A7="","",IFERROR(INDEX('ISV Inventory'!$X$6:$X$255,MATCH(SMALL('ISV Inventory'!$AU$6:$AU$255,$A7),'ISV Inventory'!$AU$6:$AU$255,0))&"","")) | I7: =IF($A7="","",IFERROR(INDEX('ISV Inventory'!$Z$6:$Z$255,MATCH(SMALL('ISV Inventory'!$AU$6:$AU$255,$A7),'ISV Inventory'!$AU$6:$AU$255,0)),"")) | J7: =IF($A7="","",IFERROR(INDEX('ISV Inventory'!$AG$6:$AG$255,MATCH(SMALL('ISV Inventory'!$AU$6:$AU$255,$A7),'ISV Inventory'!$AU$6:$AU$255,0))&"","")) | K7: =IF($A7="","",IFERROR(INDEX('ISV Inventory'!$AK$6:$AK$255,MATCH(SMALL('ISV Inventory'!$AU$6:$AU$255,$A7),'ISV Inventory'!$AU$6:$AU$255,0))&"","")) | L7: =IF($A7="","",IFERROR(INDEX('ISV Inventory'!$AR$6:$AR$255,MATCH(SMALL('ISV Inventory'!$AU$6:$AU$255,$A7),'ISV Inventory'!$AU$6:$AU$255,0))&"","")) | M7: =IF($A7="","",IFERROR(INDEX('ISV Inventory'!$AS$6:$AS$255,MATCH(SMALL('ISV Inventory'!$AU$6:$AU$255,$A7),'ISV Inventory'!$AU$6:$AU$255,0))&"",""))
A8: =IF(COUNT('ISV Inventory'!$AU$6:$AU$255)<4,"",4) | B8: =IF($A8="","",IFERROR(INDEX('ISV Inventory'!$V$6:$V$255,MATCH(SMALL('ISV Inventory'!$AU$6:$AU$255,$A8),'ISV Inventory'!$AU$6:$AU$255,0)),"")) | C8: =IF($A8="","",IFERROR(INDEX('ISV Inventory'!$AA$6:$AA$255,MATCH(SMALL('ISV Inventory'!$AU$6:$AU$255,$A8),'ISV Inventory'!$AU$6:$AU$255,0)),"")) | D8: =IF($A8="","",IFERROR(INDEX('ISV Inventory'!$AB$6:$AB$255,MATCH(SMALL('ISV Inventory'!$AU$6:$AU$255,$A8),'ISV Inventory'!$AU$6:$AU$255,0))&"","")) | E8: =IF($A8="","",IFERROR(INDEX('ISV Inventory'!$B$6:$B$255,MATCH(SMALL('ISV Inventory'!$AU$6:$AU$255,$A8),'ISV Inventory'!$AU$6:$AU$255,0))&"","")) | F8: =IF($A8="","",IFERROR(INDEX('ISV Inventory'!$F$6:$F$255,MATCH(SMALL('ISV Inventory'!$AU$6:$AU$255,$A8),'ISV Inventory'!$AU$6:$AU$255,0))&"","")) | G8: =IF($A8="","",IFERROR(INDEX('ISV Inventory'!$R$6:$R$255,MATCH(SMALL('ISV Inventory'!$AU$6:$AU$255,$A8),'ISV Inventory'!$AU$6:$AU$255,0)),"")) | H8: =IF($A8="","",IFERROR(INDEX('ISV Inventory'!$X$6:$X$255,MATCH(SMALL('ISV Inventory'!$AU$6:$AU$255,$A8),'ISV Inventory'!$AU$6:$AU$255,0))&"","")) | I8: =IF($A8="","",IFERROR(INDEX('ISV Inventory'!$Z$6:$Z$255,MATCH(SMALL('ISV Inventory'!$AU$6:$AU$255,$A8),'ISV Inventory'!$AU$6:$AU$255,0)),"")) | J8: =IF($A8="","",IFERROR(INDEX('ISV Inventory'!$AG$6:$AG$255,MATCH(SMALL('ISV Inventory'!$AU$6:$AU$255,$A8),'ISV Inventory'!$AU$6:$AU$255,0))&"","")) | K8: =IF($A8="","",IFERROR(INDEX('ISV Inventory'!$AK$6:$AK$255,MATCH(SMALL('ISV Inventory'!$AU$6:$AU$255,$A8),'ISV Inventory'!$AU$6:$AU$255,0))&"","")) | L8: =IF($A8="","",IFERROR(INDEX('ISV Inventory'!$AR$6:$AR$255,MATCH(SMALL('ISV Inventory'!$AU$6:$AU$255,$A8),'ISV Inventory'!$AU$6:$AU$255,0))&"","")) | M8: =IF($A8="","",IFERROR(INDEX('ISV Inventory'!$AS$6:$AS$255,MATCH(SMALL('ISV Inventory'!$AU$6:$AU$255,$A8),'ISV Inventory'!$AU$6:$AU$255,0))&"",""))
A9: =IF(COUNT('ISV Inventory'!$AU$6:$AU$255)<5,"",5) | B9: =IF($A9="","",IFERROR(INDEX('ISV Inventory'!$V$6:$V$255,MATCH(SMALL('ISV Inventory'!$AU$6:$AU$255,$A9),'ISV Inventory'!$AU$6:$AU$255,0)),"")) | C9: =IF($A9="","",IFERROR(INDEX('ISV Inventory'!$AA$6:$AA$255,MATCH(SMALL('ISV Inventory'!$AU$6:$AU$255,$A9),'ISV Inventory'!$AU$6:$AU$255,0)),"")) | D9: =IF($A9="","",IFERROR(INDEX('ISV Inventory'!$AB$6:$AB$255,MATCH(SMALL('ISV Inventory'!$AU$6:$AU$255,$A9),'ISV Inventory'!$AU$6:$AU$255,0))&"","")) | E9: =IF($A9="","",IFERROR(INDEX('ISV Inventory'!$B$6:$B$255,MATCH(SMALL('ISV Inventory'!$AU$6:$AU$255,$A9),'ISV Inventory'!$AU$6:$AU$255,0))&"","")) | F9: =IF($A9="","",IFERROR(INDEX('ISV Inventory'!$F$6:$F$255,MATCH(SMALL('ISV Inventory'!$AU$6:$AU$255,$A9),'ISV Inventory'!$AU$6:$AU$255,0))&"","")) | G9: =IF($A9="","",IFERROR(INDEX('ISV Inventory'!$R$6:$R$255,MATCH(SMALL('ISV Inventory'!$AU$6:$AU$255,$A9),'ISV Inventory'!$AU$6:$AU$255,0)),"")) | H9: =IF($A9="","",IFERROR(INDEX('ISV Inventory'!$X$6:$X$255,MATCH(SMALL('ISV Inventory'!$AU$6:$AU$255,$A9),'ISV Inventory'!$AU$6:$AU$255,0))&"","")) | I9: =IF($A9="","",IFERROR(INDEX('ISV Inventory'!$Z$6:$Z$255,MATCH(SMALL('ISV Inventory'!$AU$6:$AU$255,$A9),'ISV Inventory'!$AU$6:$AU$255,0)),"")) | J9: =IF($A9="","",IFERROR(INDEX('ISV Inventory'!$AG$6:$AG$255,MATCH(SMALL('ISV Inventory'!$AU$6:$AU$255,$A9),'ISV Inventory'!$AU$6:$AU$255,0))&"","")) | K9: =IF($A9="","",IFERROR(INDEX('ISV Inventory'!$AK$6:$AK$255,MATCH(SMALL('ISV Inventory'!$AU$6:$AU$255,$A9),'ISV Inventory'!$AU$6:$AU$255,0))&"","")) | L9: =IF($A9="","",IFERROR(INDEX('ISV Inventory'!$AR$6:$AR$255,MATCH(SMALL('ISV Inventory'!$AU$6:$AU$255,$A9),'ISV Inventory'!$AU$6:$AU$255,0))&"","")) | M9: =IF($A9="","",IFERROR(INDEX('ISV Inventory'!$AS$6:$AS$255,MATCH(SMALL('ISV Inventory'!$AU$6:$AU$255,$A9),'ISV Inventory'!$AU$6:$AU$255,0))&"",""))
A10: =IF(COUNT('ISV Inventory'!$AU$6:$AU$255)<6,"",6) | B10: =IF($A10="","",IFERROR(INDEX('ISV Inventory'!$V$6:$V$255,MATCH(SMALL('ISV Inventory'!$AU$6:$AU$255,$A10),'ISV Inventory'!$AU$6:$AU$255,0)),"")) | C10: =IF($A10="","",IFERROR(INDEX('ISV Inventory'!$AA$6:$AA$255,MATCH(SMALL('ISV Inventory'!$AU$6:$AU$255,$A10),'ISV Inventory'!$AU$6:$AU$255,0)),"")) | D10: =IF($A10="","",IFERROR(INDEX('ISV Inventory'!$AB$6:$AB$255,MATCH(SMALL('ISV Inventory'!$AU$6:$AU$255,$A10),'ISV Inventory'!$AU$6:$AU$255,0))&"","")) | E10: =IF($A10="","",IFERROR(INDEX('ISV Inventory'!$B$6:$B$255,MATCH(SMALL('ISV Inventory'!$AU$6:$AU$255,$A10),'ISV Inventory'!$AU$6:$AU$255,0))&"","")) | F10: =IF($A10="","",IFERROR(INDEX('ISV Inventory'!$F$6:$F$255,MATCH(SMALL('ISV Inventory'!$AU$6:$AU$255,$A10),'ISV Inventory'!$AU$6:$AU$255,0))&"","")) | G10: =IF($A10="","",IFERROR(INDEX('ISV Inventory'!$R$6:$R$255,MATCH(SMALL('ISV Inventory'!$AU$6:$AU$255,$A10),'ISV Inventory'!$AU$6:$AU$255,0)),"")) | H10: =IF($A10="","",IFERROR(INDEX('ISV Inventory'!$X$6:$X$255,MATCH(SMALL('ISV Inventory'!$AU$6:$AU$255,$A10),'ISV Inventory'!$AU$6:$AU$255,0))&"","")) | I10: =IF($A10="","",IFERROR(INDEX('ISV Inventory'!$Z$6:$Z$255,MATCH(SMALL('ISV Inventory'!$AU$6:$AU$255,$A10),'ISV Inventory'!$AU$6:$AU$255,0)),"")) | J10: =IF($A10="","",IFERROR(INDEX('ISV Inventory'!$AG$6:$AG$255,MATCH(SMALL('ISV Inventory'!$AU$6:$AU$255,$A10),'ISV Inventory'!$AU$6:$AU$255,0))&"","")) | K10: =IF($A10="","",IFERROR(INDEX('ISV Inventory'!$AK$6:$AK$255,MATCH(SMALL('ISV Inventory'!$AU$6:$AU$255,$A10),'ISV Inventory'!$AU$6:$AU$255,0))&"","")) | L10: =IF($A10="","",IFERROR(INDEX('ISV Inventory'!$AR$6:$AR$255,MATCH(SMALL('ISV Inventory'!$AU$6:$AU$255,$A10),'ISV Inventory'!$AU$6:$AU$255,0))&"","")) | M10: =IF($A10="","",IFERROR(INDEX('ISV Inventory'!$AS$6:$AS$255,MATCH(SMALL('ISV Inventory'!$AU$6:$AU$255,$A10),'ISV Inventory'!$AU$6:$AU$255,0))&"",""))
A11: =IF(COUNT('ISV Inventory'!$AU$6:$AU$255)<7,"",7) | B11: =IF($A11="","",IFERROR(INDEX('ISV Inventory'!$V$6:$V$255,MATCH(SMALL('ISV Inventory'!$AU$6:$AU$255,$A11),'ISV Inventory'!$AU$6:$AU$255,0)),"")) | C11: =IF($A11="","",IFERROR(INDEX('ISV Inventory'!$AA$6:$AA$255,MATCH(SMALL('ISV Inventory'!$AU$6:$AU$255,$A11),'ISV Inventory'!$AU$6:$AU$255,0)),"")) | D11: =IF($A11="","",IFERROR(INDEX('ISV Inventory'!$AB$6:$AB$255,MATCH(SMALL('ISV Inventory'!$AU$6:$AU$255,$A11),'ISV Inventory'!$AU$6:$AU$255,0))&"","")) | E11: =IF($A11="","",IFERROR(INDEX('ISV Inventory'!$B$6:$B$255,MATCH(SMALL('ISV Inventory'!$AU$6:$AU$255,$A11),'ISV Inventory'!$AU$6:$AU$255,0))&"","")) | F11: =IF($A11="","",IFERROR(INDEX('ISV Inventory'!$F$6:$F$255,MATCH(SMALL('ISV Inventory'!$AU$6:$AU$255,$A11),'ISV Inventory'!$AU$6:$AU$255,0))&"","")) | G11: =IF($A11="","",IFERROR(INDEX('ISV Inventory'!$R$6:$R$255,MATCH(SMALL('ISV Inventory'!$AU$6:$AU$255,$A11),'ISV Inventory'!$AU$6:$AU$255,0)),"")) | H11: =IF($A11="","",IFERROR(INDEX('ISV Inventory'!$X$6:$X$255,MATCH(SMALL('ISV Inventory'!$AU$6:$AU$255,$A11),'ISV Inventory'!$AU$6:$AU$255,0))&"","")) | I11: =IF($A11="","",IFERROR(INDEX('ISV Inventory'!$Z$6:$Z$255,MATCH(SMALL('ISV Inventory'!$AU$6:$AU$255,$A11),'ISV Inventory'!$AU$6:$AU$255,0)),"")) | J11: =IF($A11="","",IFERROR(INDEX('ISV Inventory'!$AG$6:$AG$255,MATCH(SMALL('ISV Inventory'!$AU$6:$AU$255,$A11),'ISV Inventory'!$AU$6:$AU$255,0))&"","")) | K11: =IF($A11="","",IFERROR(INDEX('ISV Inventory'!$AK$6:$AK$255,MATCH(SMALL('ISV Inventory'!$AU$6:$AU$255,$A11),'ISV Inventory'!$AU$6:$AU$255,0))&"","")) | L11: =IF($A11="","",IFERROR(INDEX('ISV Inventory'!$AR$6:$AR$255,MATCH(SMALL('ISV Inventory'!$AU$6:$AU$255,$A11),'ISV Inventory'!$AU$6:$AU$255,0))&"","")) | M11: =IF($A11="","",IFERROR(INDEX('ISV Inventory'!$AS$6:$AS$255,MATCH(SMALL('ISV Inventory'!$AU$6:$AU$255,$A11),'ISV Inventory'!$AU$6:$AU$255,0))&"",""))
A12: =IF(COUNT('ISV Inventory'!$AU$6:$AU$255)<8,"",8) | B12: =IF($A12="","",IFERROR(INDEX('ISV Inventory'!$V$6:$V$255,MATCH(SMALL('ISV Inventory'!$AU$6:$AU$255,$A12),'ISV Inventory'!$AU$6:$AU$255,0)),"")) | C12: =IF($A12="","",IFERROR(INDEX('ISV Inventory'!$AA$6:$AA$255,MATCH(SMALL('ISV Inventory'!$AU$6:$AU$255,$A12),'ISV Inventory'!$AU$6:$AU$255,0)),"")) | D12: =IF($A12="","",IFERROR(INDEX('ISV Inventory'!$AB$6:$AB$255,MATCH(SMALL('ISV Inventory'!$AU$6:$AU$255,$A12),'ISV Inventory'!$AU$6:$AU$255,0))&"","")) | E12: =IF($A12="","",IFERROR(INDEX('ISV Inventory'!$B$6:$B$255,MATCH(SMALL('ISV Inventory'!$AU$6:$AU$255,$A12),'ISV Inventory'!$AU$6:$AU$255,0))&"","")) | F12: =IF($A12="","",IFERROR(INDEX('ISV Inventory'!$F$6:$F$255,MATCH(SMALL('ISV Inventory'!$AU$6:$AU$255,$A12),'ISV Inventory'!$AU$6:$AU$255,0))&"","")) | G12: =IF($A12="","",IFERROR(INDEX('ISV Inventory'!$R$6:$R$255,MATCH(SMALL('ISV Inventory'!$AU$6:$AU$255,$A12),'ISV Inventory'!$AU$6:$AU$255,0)),"")) | H12: =IF($A12="","",IFERROR(INDEX('ISV Inventory'!$X$6:$X$255,MATCH(SMALL('ISV Inventory'!$AU$6:$AU$255,$A12),'ISV Inventory'!$AU$6:$AU$255,0))&"","")) | I12: =IF($A12="","",IFERROR(INDEX('ISV Inventory'!$Z$6:$Z$255,MATCH(SMALL('ISV Inventory'!$AU$6:$AU$255,$A12),'ISV Inventory'!$AU$6:$AU$255,0)),"")) | J12: =IF($A12="","",IFERROR(INDEX('ISV Inventory'!$AG$6:$AG$255,MATCH(SMALL('ISV Inventory'!$AU$6:$AU$255,$A12),'ISV Inventory'!$AU$6:$AU$255,0))&"","")) | K12: =IF($A12="","",IFERROR(INDEX('ISV Inventory'!$AK$6:$AK$255,MATCH(SMALL('ISV Inventory'!$AU$6:$AU$255,$A12),'ISV Inventory'!$AU$6:$AU$255,0))&"","")) | L12: =IF($A12="","",IFERROR(INDEX('ISV Inventory'!$AR$6:$AR$255,MATCH(SMALL('ISV Inventory'!$AU$6:$AU$255,$A12),'ISV Inventory'!$AU$6:$AU$255,0))&"","")) | M12: =IF($A12="","",IFERROR(INDEX('ISV Inventory'!$AS$6:$AS$255,MATCH(SMALL('ISV Inventory'!$AU$6:$AU$255,$A12),'ISV Inventory'!$AU$6:$AU$255,0))&"",""))
A13: =IF(COUNT('ISV Inventory'!$AU$6:$AU$255)<9,"",9) | B13: =IF($A13="","",IFERROR(INDEX('ISV Inventory'!$V$6:$V$255,MATCH(SMALL('ISV Inventory'!$AU$6:$AU$255,$A13),'ISV Inventory'!$AU$6:$AU$255,0)),"")) | C13: =IF($A13="","",IFERROR(INDEX('ISV Inventory'!$AA$6:$AA$255,MATCH(SMALL('ISV Inventory'!$AU$6:$AU$255,$A13),'ISV Inventory'!$AU$6:$AU$255,0)),"")) | D13: =IF($A13="","",IFERROR(INDEX('ISV Inventory'!$AB$6:$AB$255,MATCH(SMALL('ISV Inventory'!$AU$6:$AU$255,$A13),'ISV Inventory'!$AU$6:$AU$255,0))&"","")) | E13: =IF($A13="","",IFERROR(INDEX('ISV Inventory'!$B$6:$B$255,MATCH(SMALL('ISV Inventory'!$AU$6:$AU$255,$A13),'ISV Inventory'!$AU$6:$AU$255,0))&"","")) | F13: =IF($A13="","",IFERROR(INDEX('ISV Inventory'!$F$6:$F$255,MATCH(SMALL('ISV Inventory'!$AU$6:$AU$255,$A13),'ISV Inventory'!$AU$6:$AU$255,0))&"","")) | G13: =IF($A13="","",IFERROR(INDEX('ISV Inventory'!$R$6:$R$255,MATCH(SMALL('ISV Inventory'!$AU$6:$AU$255,$A13),'ISV Inventory'!$AU$6:$AU$255,0)),"")) | H13: =IF($A13="","",IFERROR(INDEX('ISV Inventory'!$X$6:$X$255,MATCH(SMALL('ISV Inventory'!$AU$6:$AU$255,$A13),'ISV Inventory'!$AU$6:$AU$255,0))&"","")) | I13: =IF($A13="","",IFERROR(INDEX('ISV Inventory'!$Z$6:$Z$255,MATCH(SMALL('ISV Inventory'!$AU$6:$AU$255,$A13),'ISV Inventory'!$AU$6:$AU$255,0)),"")) | J13: =IF($A13="","",IFERROR(INDEX('ISV Inventory'!$AG$6:$AG$255,MATCH(SMALL('ISV Inventory'!$AU$6:$AU$255,$A13),'ISV Inventory'!$AU$6:$AU$255,0))&"","")) | K13: =IF($A13="","",IFERROR(INDEX('ISV Inventory'!$AK$6:$AK$255,MATCH(SMALL('ISV Inventory'!$AU$6:$AU$255,$A13),'ISV Inventory'!$AU$6:$AU$255,0))&"","")) | L13: =IF($A13="","",IFERROR(INDEX('ISV Inventory'!$AR$6:$AR$255,MATCH(SMALL('ISV Inventory'!$AU$6:$AU$255,$A13),'ISV Inventory'!$AU$6:$AU$255,0))&"","")) | M13: =IF($A13="","",IFERROR(INDEX('ISV Inventory'!$AS$6:$AS$255,MATCH(SMALL('ISV Inventory'!$AU$6:$AU$255,$A13),'ISV Inventory'!$AU$6:$AU$255,0))&"",""))
A14: =IF(COUNT('ISV Inventory'!$AU$6:$AU$255)<10,"",10) | B14: =IF($A14="","",IFERROR(INDEX('ISV Inventory'!$V$6:$V$255,MATCH(SMALL('ISV Inventory'!$AU$6:$AU$255,$A14),'ISV Inventory'!$AU$6:$AU$255,0)),"")) | C14: =IF($A14="","",IFERROR(INDEX('ISV Inventory'!$AA$6:$AA$255,MATCH(SMALL('ISV Inventory'!$AU$6:$AU$255,$A14),'ISV Inventory'!$AU$6:$AU$255,0)),"")) | D14: =IF($A14="","",IFERROR(INDEX('ISV Inventory'!$AB$6:$AB$255,MATCH(SMALL('ISV Inventory'!$AU$6:$AU$255,$A14),'ISV Inventory'!$AU$6:$AU$255,0))&"","")) | E14: =IF($A14="","",IFERROR(INDEX('ISV Inventory'!$B$6:$B$255,MATCH(SMALL('ISV Inventory'!$AU$6:$AU$255,$A14),'ISV Inventory'!$AU$6:$AU$255,0))&"","")) | F14: =IF($A14="","",IFERROR(INDEX('ISV Inventory'!$F$6:$F$255,MATCH(SMALL('ISV Inventory'!$AU$6:$AU$255,$A14),'ISV Inventory'!$AU$6:$AU$255,0))&"","")) | G14: =IF($A14="","",IFERROR(INDEX('ISV Inventory'!$R$6:$R$255,MATCH(SMALL('ISV Inventory'!$AU$6:$AU$255,$A14),'ISV Inventory'!$AU$6:$AU$255,0)),"")) | H14: =IF($A14="","",IFERROR(INDEX('ISV Inventory'!$X$6:$X$255,MATCH(SMALL('ISV Inventory'!$AU$6:$AU$255,$A14),'ISV Inventory'!$AU$6:$AU$255,0))&"","")) | I14: =IF($A14="","",IFERROR(INDEX('ISV Inventory'!$Z$6:$Z$255,MATCH(SMALL('ISV Inventory'!$AU$6:$AU$255,$A14),'ISV Inventory'!$AU$6:$AU$255,0)),"")) | J14: =IF($A14="","",IFERROR(INDEX('ISV Inventory'!$AG$6:$AG$255,MATCH(SMALL('ISV Inventory'!$AU$6:$AU$255,$A14),'ISV Inventory'!$AU$6:$AU$255,0))&"","")) | K14: =IF($A14="","",IFERROR(INDEX('ISV Inventory'!$AK$6:$AK$255,MATCH(SMALL('ISV Inventory'!$AU$6:$AU$255,$A14),'ISV Inventory'!$AU$6:$AU$255,0))&"","")) | L14: =IF($A14="","",IFERROR(INDEX('ISV Inventory'!$AR$6:$AR$255,MATCH(SMALL('ISV Inventory'!$AU$6:$AU$255,$A14),'ISV Inventory'!$AU$6:$AU$255,0))&"","")) | M14: =IF($A14="","",IFERROR(INDEX('ISV Inventory'!$AS$6:$AS$255,MATCH(SMALL('ISV Inventory'!$AU$6:$AU$255,$A14),'ISV Inventory'!$AU$6:$AU$255,0))&"",""))
A15: =IF(COUNT('ISV Inventory'!$AU$6:$AU$255)<11,"",11) | B15: =IF($A15="","",IFERROR(INDEX('ISV Inventory'!$V$6:$V$255,MATCH(SMALL('ISV Inventory'!$AU$6:$AU$255,$A15),'ISV Inventory'!$AU$6:$AU$255,0)),"")) | C15: =IF($A15="","",IFERROR(INDEX('ISV Inventory'!$AA$6:$AA$255,MATCH(SMALL('ISV Inventory'!$AU$6:$AU$255,$A15),'ISV Inventory'!$AU$6:$AU$255,0)),"")) | D15: =IF($A15="","",IFERROR(INDEX('ISV Inventory'!$AB$6:$AB$255,MATCH(SMALL('ISV Inventory'!$AU$6:$AU$255,$A15),'ISV Inventory'!$AU$6:$AU$255,0))&"","")) | E15: =IF($A15="","",IFERROR(INDEX('ISV Inventory'!$B$6:$B$255,MATCH(SMALL('ISV Inventory'!$AU$6:$AU$255,$A15),'ISV Inventory'!$AU$6:$AU$255,0))&"","")) | F15: =IF($A15="","",IFERROR(INDEX('ISV Inventory'!$F$6:$F$255,MATCH(SMALL('ISV Inventory'!$AU$6:$AU$255,$A15),'ISV Inventory'!$AU$6:$AU$255,0))&"","")) | G15: =IF($A15="","",IFERROR(INDEX('ISV Inventory'!$R$6:$R$255,MATCH(SMALL('ISV Inventory'!$AU$6:$AU$255,$A15),'ISV Inventory'!$AU$6:$AU$255,0)),"")) | H15: =IF($A15="","",IFERROR(INDEX('ISV Inventory'!$X$6:$X$255,MATCH(SMALL('ISV Inventory'!$AU$6:$AU$255,$A15),'ISV Inventory'!$AU$6:$AU$255,0))&"","")) | I15: =IF($A15="","",IFERROR(INDEX('ISV Inventory'!$Z$6:$Z$255,MATCH(SMALL('ISV Inventory'!$AU$6:$AU$255,$A15),'ISV Inventory'!$AU$6:$AU$255,0)),"")) | J15: =IF($A15="","",IFERROR(INDEX('ISV Inventory'!$AG$6:$AG$255,MATCH(SMALL('ISV Inventory'!$AU$6:$AU$255,$A15),'ISV Inventory'!$AU$6:$AU$255,0))&"","")) | K15: =IF($A15="","",IFERROR(INDEX('ISV Inventory'!$AK$6:$AK$255,MATCH(SMALL('ISV Inventory'!$AU$6:$AU$255,$A15),'ISV Inventory'!$AU$6:$AU$255,0))&"","")) | L15: =IF($A15="","",IFERROR(INDEX('ISV Inventory'!$AR$6:$AR$255,MATCH(SMALL('ISV Inventory'!$AU$6:$AU$255,$A15),'ISV Inventory'!$AU$6:$AU$255,0))&"","")) | M15: =IF($A15="","",IFERROR(INDEX('ISV Inventory'!$AS$6:$AS$255,MATCH(SMALL('ISV Inventory'!$AU$6:$AU$255,$A15),'ISV Inventory'!$AU$6:$AU$255,0))&"",""))
A16: =IF(COUNT('ISV Inventory'!$AU$6:$AU$255)<12,"",12) | B16: =IF($A16="","",IFERROR(INDEX('ISV Inventory'!$V$6:$V$255,MATCH(SMALL('ISV Inventory'!$AU$6:$AU$255,$A16),'ISV Inventory'!$AU$6:$AU$255,0)),"")) | C16: =IF($A16="","",IFERROR(INDEX('ISV Inventory'!$AA$6:$AA$255,MATCH(SMALL('ISV Inventory'!$AU$6:$AU$255,$A16),'ISV Inventory'!$AU$6:$AU$255,0)),"")) | D16: =IF($A16="","",IFERROR(INDEX('ISV Inventory'!$AB$6:$AB$255,MATCH(SMALL('ISV Inventory'!$AU$6:$AU$255,$A16),'ISV Inventory'!$AU$6:$AU$255,0))&"","")) | E16: =IF($A16="","",IFERROR(INDEX('ISV Inventory'!$B$6:$B$255,MATCH(SMALL('ISV Inventory'!$AU$6:$AU$255,$A16),'ISV Inventory'!$AU$6:$AU$255,0))&"","")) | F16: =IF($A16="","",IFERROR(INDEX('ISV Inventory'!$F$6:$F$255,MATCH(SMALL('ISV Inventory'!$AU$6:$AU$255,$A16),'ISV Inventory'!$AU$6:$AU$255,0))&"","")) | G16: =IF($A16="","",IFERROR(INDEX('ISV Inventory'!$R$6:$R$255,MATCH(SMALL('ISV Inventory'!$AU$6:$AU$255,$A16),'ISV Inventory'!$AU$6:$AU$255,0)),"")) | H16: =IF($A16="","",IFERROR(INDEX('ISV Inventory'!$X$6:$X$255,MATCH(SMALL('ISV Inventory'!$AU$6:$AU$255,$A16),'ISV Inventory'!$AU$6:$AU$255,0))&"","")) | I16: =IF($A16="","",IFERROR(INDEX('ISV Inventory'!$Z$6:$Z$255,MATCH(SMALL('ISV Inventory'!$AU$6:$AU$255,$A16),'ISV Inventory'!$AU$6:$AU$255,0)),"")) | J16: =IF($A16="","",IFERROR(INDEX('ISV Inventory'!$AG$6:$AG$255,MATCH(SMALL('ISV Inventory'!$AU$6:$AU$255,$A16),'ISV Inventory'!$AU$6:$AU$255,0))&"","")) | K16: =IF($A16="","",IFERROR(INDEX('ISV Inventory'!$AK$6:$AK$255,MATCH(SMALL('ISV Inventory'!$AU$6:$AU$255,$A16),'ISV Inventory'!$AU$6:$AU$255,0))&"","")) | L16: =IF($A16="","",IFERROR(INDEX('ISV Inventory'!$AR$6:$AR$255,MATCH(SMALL('ISV Inventory'!$AU$6:$AU$255,$A16),'ISV Inventory'!$AU$6:$AU$255,0))&"","")) | M16: =IF($A16="","",IFERROR(INDEX('ISV Inventory'!$AS$6:$AS$255,MATCH(SMALL('ISV Inventory'!$AU$6:$AU$255,$A16),'ISV Inventory'!$AU$6:$AU$255,0))&"",""))
A17: =IF(COUNT('ISV Inventory'!$AU$6:$AU$255)<13,"",13) | B17: =IF($A17="","",IFERROR(INDEX('ISV Inventory'!$V$6:$V$255,MATCH(SMALL('ISV Inventory'!$AU$6:$AU$255,$A17),'ISV Inventory'!$AU$6:$AU$255,0)),"")) | C17: =IF($A17="","",IFERROR(INDEX('ISV Inventory'!$AA$6:$AA$255,MATCH(SMALL('ISV Inventory'!$AU$6:$AU$255,$A17),'ISV Inventory'!$AU$6:$AU$255,0)),"")) | D17: =IF($A17="","",IFERROR(INDEX('ISV Inventory'!$AB$6:$AB$255,MATCH(SMALL('ISV Inventory'!$AU$6:$AU$255,$A17),'ISV Inventory'!$AU$6:$AU$255,0))&"","")) | E17: =IF($A17="","",IFERROR(INDEX('ISV Inventory'!$B$6:$B$255,MATCH(SMALL('ISV Inventory'!$AU$6:$AU$255,$A17),'ISV Inventory'!$AU$6:$AU$255,0))&"","")) | F17: =IF($A17="","",IFERROR(INDEX('ISV Inventory'!$F$6:$F$255,MATCH(SMALL('ISV Inventory'!$AU$6:$AU$255,$A17),'ISV Inventory'!$AU$6:$AU$255,0))&"","")) | G17: =IF($A17="","",IFERROR(INDEX('ISV Inventory'!$R$6:$R$255,MATCH(SMALL('ISV Inventory'!$AU$6:$AU$255,$A17),'ISV Inventory'!$AU$6:$AU$255,0)),"")) | H17: =IF($A17="","",IFERROR(INDEX('ISV Inventory'!$X$6:$X$255,MATCH(SMALL('ISV Inventory'!$AU$6:$AU$255,$A17),'ISV Inventory'!$AU$6:$AU$255,0))&"","")) | I17: =IF($A17="","",IFERROR(INDEX('ISV Inventory'!$Z$6:$Z$255,MATCH(SMALL('ISV Inventory'!$AU$6:$AU$255,$A17),'ISV Inventory'!$AU$6:$AU$255,0)),"")) | J17: =IF($A17="","",IFERROR(INDEX('ISV Inventory'!$AG$6:$AG$255,MATCH(SMALL('ISV Inventory'!$AU$6:$AU$255,$A17),'ISV Inventory'!$AU$6:$AU$255,0))&"","")) | K17: =IF($A17="","",IFERROR(INDEX('ISV Inventory'!$AK$6:$AK$255,MATCH(SMALL('ISV Inventory'!$AU$6:$AU$255,$A17),'ISV Inventory'!$AU$6:$AU$255,0))&"","")) | L17: =IF($A17="","",IFERROR(INDEX('ISV Inventory'!$AR$6:$AR$255,MATCH(SMALL('ISV Inventory'!$AU$6:$AU$255,$A17),'ISV Inventory'!$AU$6:$AU$255,0))&"","")) | M17: =IF($A17="","",IFERROR(INDEX('ISV Inventory'!$AS$6:$AS$255,MATCH(SMALL('ISV Inventory'!$AU$6:$AU$255,$A17),'ISV Inventory'!$AU$6:$AU$255,0))&"",""))
A18: =IF(COUNT('ISV Inventory'!$AU$6:$AU$255)<14,"",14) | B18: =IF($A18="","",IFERROR(INDEX('ISV Inventory'!$V$6:$V$255,MATCH(SMALL('ISV Inventory'!$AU$6:$AU$255,$A18),'ISV Inventory'!$AU$6:$AU$255,0)),"")) | C18: =IF($A18="","",IFERROR(INDEX('ISV Inventory'!$AA$6:$AA$255,MATCH(SMALL('ISV Inventory'!$AU$6:$AU$255,$A18),'ISV Inventory'!$AU$6:$AU$255,0)),"")) | D18: =IF($A18="","",IFERROR(INDEX('ISV Inventory'!$AB$6:$AB$255,MATCH(SMALL('ISV Inventory'!$AU$6:$AU$255,$A18),'ISV Inventory'!$AU$6:$AU$255,0))&"","")) | E18: =IF($A18="","",IFERROR(INDEX('ISV Inventory'!$B$6:$B$255,MATCH(SMALL('ISV Inventory'!$AU$6:$AU$255,$A18),'ISV Inventory'!$AU$6:$AU$255,0))&"","")) | F18: =IF($A18="","",IFERROR(INDEX('ISV Inventory'!$F$6:$F$255,MATCH(SMALL('ISV Inventory'!$AU$6:$AU$255,$A18),'ISV Inventory'!$AU$6:$AU$255,0))&"","")) | G18: =IF($A18="","",IFERROR(INDEX('ISV Inventory'!$R$6:$R$255,MATCH(SMALL('ISV Inventory'!$AU$6:$AU$255,$A18),'ISV Inventory'!$AU$6:$AU$255,0)),"")) | H18: =IF($A18="","",IFERROR(INDEX('ISV Inventory'!$X$6:$X$255,MATCH(SMALL('ISV Inventory'!$AU$6:$AU$255,$A18),'ISV Inventory'!$AU$6:$AU$255,0))&"","")) | I18: =IF($A18="","",IFERROR(INDEX('ISV Inventory'!$Z$6:$Z$255,MATCH(SMALL('ISV Inventory'!$AU$6:$AU$255,$A18),'ISV Inventory'!$AU$6:$AU$255,0)),"")) | J18: =IF($A18="","",IFERROR(INDEX('ISV Inventory'!$AG$6:$AG$255,MATCH(SMALL('ISV Inventory'!$AU$6:$AU$255,$A18),'ISV Inventory'!$AU$6:$AU$255,0))&"","")) | K18: =IF($A18="","",IFERROR(INDEX('ISV Inventory'!$AK$6:$AK$255,MATCH(SMALL('ISV Inventory'!$AU$6:$AU$255,$A18),'ISV Inventory'!$AU$6:$AU$255,0))&"","")) | L18: =IF($A18="","",IFERROR(INDEX('ISV Inventory'!$AR$6:$AR$255,MATCH(SMALL('ISV Inventory'!$AU$6:$AU$255,$A18),'ISV Inventory'!$AU$6:$AU$255,0))&"","")) | M18: =IF($A18="","",IFERROR(INDEX('ISV Inventory'!$AS$6:$AS$255,MATCH(SMALL('ISV Inventory'!$AU$6:$AU$255,$A18),'ISV Inventory'!$AU$6:$AU$255,0))&"",""))
A19: =IF(COUNT('ISV Inventory'!$AU$6:$AU$255)<15,"",15) | B19: =IF($A19="","",IFERROR(INDEX('ISV Inventory'!$V$6:$V$255,MATCH(SMALL('ISV Inventory'!$AU$6:$AU$255,$A19),'ISV Inventory'!$AU$6:$AU$255,0)),"")) | C19: =IF($A19="","",IFERROR(INDEX('ISV Inventory'!$AA$6:$AA$255,MATCH(SMALL('ISV Inventory'!$AU$6:$AU$255,$A19),'ISV Inventory'!$AU$6:$AU$255,0)),"")) | D19: =IF($A19="","",IFERROR(INDEX('ISV Inventory'!$AB$6:$AB$255,MATCH(SMALL('ISV Inventory'!$AU$6:$AU$255,$A19),'ISV Inventory'!$AU$6:$AU$255,0))&"","")) | E19: =IF($A19="","",IFERROR(INDEX('ISV Inventory'!$B$6:$B$255,MATCH(SMALL('ISV Inventory'!$AU$6:$AU$255,$A19),'ISV Inventory'!$AU$6:$AU$255,0))&"","")) | F19: =IF($A19="","",IFERROR(INDEX('ISV Inventory'!$F$6:$F$255,MATCH(SMALL('ISV Inventory'!$AU$6:$AU$255,$A19),'ISV Inventory'!$AU$6:$AU$255,0))&"","")) | G19: =IF($A19="","",IFERROR(INDEX('ISV Inventory'!$R$6:$R$255,MATCH(SMALL('ISV Inventory'!$AU$6:$AU$255,$A19),'ISV Inventory'!$AU$6:$AU$255,0)),"")) | H19: =IF($A19="","",IFERROR(INDEX('ISV Inventory'!$X$6:$X$255,MATCH(SMALL('ISV Inventory'!$AU$6:$AU$255,$A19),'ISV Inventory'!$AU$6:$AU$255,0))&"","")) | I19: =IF($A19="","",IFERROR(INDEX('ISV Inventory'!$Z$6:$Z$255,MATCH(SMALL('ISV Inventory'!$AU$6:$AU$255,$A19),'ISV Inventory'!$AU$6:$AU$255,0)),"")) | J19: =IF($A19="","",IFERROR(INDEX('ISV Inventory'!$AG$6:$AG$255,MATCH(SMALL('ISV Inventory'!$AU$6:$AU$255,$A19),'ISV Inventory'!$AU$6:$AU$255,0))&"","")) | K19: =IF($A19="","",IFERROR(INDEX('ISV Inventory'!$AK$6:$AK$255,MATCH(SMALL('ISV Inventory'!$AU$6:$AU$255,$A19),'ISV Inventory'!$AU$6:$AU$255,0))&"","")) | L19: =IF($A19="","",IFERROR(INDEX('ISV Inventory'!$AR$6:$AR$255,MATCH(SMALL('ISV Inventory'!$AU$6:$AU$255,$A19),'ISV Inventory'!$AU$6:$AU$255,0))&"","")) | M19: =IF($A19="","",IFERROR(INDEX('ISV Inventory'!$AS$6:$AS$255,MATCH(SMALL('ISV Inventory'!$AU$6:$AU$255,$A19),'ISV Inventory'!$AU$6:$AU$255,0))&"",""))
A20: =IF(COUNT('ISV Inventory'!$AU$6:$AU$255)<16,"",16) | B20: =IF($A20="","",IFERROR(INDEX('ISV Inventory'!$V$6:$V$255,MATCH(SMALL('ISV Inventory'!$AU$6:$AU$255,$A20),'ISV Inventory'!$AU$6:$AU$255,0)),"")) | C20: =IF($A20="","",IFERROR(INDEX('ISV Inventory'!$AA$6:$AA$255,MATCH(SMALL('ISV Inventory'!$AU$6:$AU$255,$A20),'ISV Inventory'!$AU$6:$AU$255,0)),"")) | D20: =IF($A20="","",IFERROR(INDEX('ISV Inventory'!$AB$6:$AB$255,MATCH(SMALL('ISV Inventory'!$AU$6:$AU$255,$A20),'ISV Inventory'!$AU$6:$AU$255,0))&"","")) | E20: =IF($A20="","",IFERROR(INDEX('ISV Inventory'!$B$6:$B$255,MATCH(SMALL('ISV Inventory'!$AU$6:$AU$255,$A20),'ISV Inventory'!$AU$6:$AU$255,0))&"","")) | F20: =IF($A20="","",IFERROR(INDEX('ISV Inventory'!$F$6:$F$255,MATCH(SMALL('ISV Inventory'!$AU$6:$AU$255,$A20),'ISV Inventory'!$AU$6:$AU$255,0))&"","")) | G20: =IF($A20="","",IFERROR(INDEX('ISV Inventory'!$R$6:$R$255,MATCH(SMALL('ISV Inventory'!$AU$6:$AU$255,$A20),'ISV Inventory'!$AU$6:$AU$255,0)),"")) | H20: =IF($A20="","",IFERROR(INDEX('ISV Inventory'!$X$6:$X$255,MATCH(SMALL('ISV Inventory'!$AU$6:$AU$255,$A20),'ISV Inventory'!$AU$6:$AU$255,0))&"","")) | I20: =IF($A20="","",IFERROR(INDEX('ISV Inventory'!$Z$6:$Z$255,MATCH(SMALL('ISV Inventory'!$AU$6:$AU$255,$A20),'ISV Inventory'!$AU$6:$AU$255,0)),"")) | J20: =IF($A20="","",IFERROR(INDEX('ISV Inventory'!$AG$6:$AG$255,MATCH(SMALL('ISV Inventory'!$AU$6:$AU$255,$A20),'ISV Inventory'!$AU$6:$AU$255,0))&"","")) | K20: =IF($A20="","",IFERROR(INDEX('ISV Inventory'!$AK$6:$AK$255,MATCH(SMALL('ISV Inventory'!$AU$6:$AU$255,$A20),'ISV Inventory'!$AU$6:$AU$255,0))&"","")) | L20: =IF($A20="","",IFERROR(INDEX('ISV Inventory'!$AR$6:$AR$255,MATCH(SMALL('ISV Inventory'!$AU$6:$AU$255,$A20),'ISV Inventory'!$AU$6:$AU$255,0))&"","")) | M20: =IF($A20="","",IFERROR(INDEX('ISV Inventory'!$AS$6:$AS$255,MATCH(SMALL('ISV Inventory'!$AU$6:$AU$255,$A20),'ISV Inventory'!$AU$6:$AU$255,0))&"",""))
A21: =IF(COUNT('ISV Inventory'!$AU$6:$AU$255)<17,"",17) | B21: =IF($A21="","",IFERROR(INDEX('ISV Inventory'!$V$6:$V$255,MATCH(SMALL('ISV Inventory'!$AU$6:$AU$255,$A21),'ISV Inventory'!$AU$6:$AU$255,0)),"")) | C21: =IF($A21="","",IFERROR(INDEX('ISV Inventory'!$AA$6:$AA$255,MATCH(SMALL('ISV Inventory'!$AU$6:$AU$255,$A21),'ISV Inventory'!$AU$6:$AU$255,0)),"")) | D21: =IF($A21="","",IFERROR(INDEX('ISV Inventory'!$AB$6:$AB$255,MATCH(SMALL('ISV Inventory'!$AU$6:$AU$255,$A21),'ISV Inventory'!$AU$6:$AU$255,0))&"","")) | E21: =IF($A21="","",IFERROR(INDEX('ISV Inventory'!$B$6:$B$255,MATCH(SMALL('ISV Inventory'!$AU$6:$AU$255,$A21),'ISV Inventory'!$AU$6:$AU$255,0))&"","")) | F21: =IF($A21="","",IFERROR(INDEX('ISV Inventory'!$F$6:$F$255,MATCH(SMALL('ISV Inventory'!$AU$6:$AU$255,$A21),'ISV Inventory'!$AU$6:$AU$255,0))&"","")) | G21: =IF($A21="","",IFERROR(INDEX('ISV Inventory'!$R$6:$R$255,MATCH(SMALL('ISV Inventory'!$AU$6:$AU$255,$A21),'ISV Inventory'!$AU$6:$AU$255,0)),"")) | H21: =IF($A21="","",IFERROR(INDEX('ISV Inventory'!$X$6:$X$255,MATCH(SMALL('ISV Inventory'!$AU$6:$AU$255,$A21),'ISV Inventory'!$AU$6:$AU$255,0))&"","")) | I21: =IF($A21="","",IFERROR(INDEX('ISV Inventory'!$Z$6:$Z$255,MATCH(SMALL('ISV Inventory'!$AU$6:$AU$255,$A21),'ISV Inventory'!$AU$6:$AU$255,0)),"")) | J21: =IF($A21="","",IFERROR(INDEX('ISV Inventory'!$AG$6:$AG$255,MATCH(SMALL('ISV Inventory'!$AU$6:$AU$255,$A21),'ISV Inventory'!$AU$6:$AU$255,0))&"","")) | K21: =IF($A21="","",IFERROR(INDEX('ISV Inventory'!$AK$6:$AK$255,MATCH(SMALL('ISV Inventory'!$AU$6:$AU$255,$A21),'ISV Inventory'!$AU$6:$AU$255,0))&"","")) | L21: =IF($A21="","",IFERROR(INDEX('ISV Inventory'!$AR$6:$AR$255,MATCH(SMALL('ISV Inventory'!$AU$6:$AU$255,$A21),'ISV Inventory'!$AU$6:$AU$255,0))&"","")) | M21: =IF($A21="","",IFERROR(INDEX('ISV Inventory'!$AS$6:$AS$255,MATCH(SMALL('ISV Inventory'!$AU$6:$AU$255,$A21),'ISV Inventory'!$AU$6:$AU$255,0))&"",""))
A22: =IF(COUNT('ISV Inventory'!$AU$6:$AU$255)<18,"",18) | B22: =IF($A22="","",IFERROR(INDEX('ISV Inventory'!$V$6:$V$255,MATCH(SMALL('ISV Inventory'!$AU$6:$AU$255,$A22),'ISV Inventory'!$AU$6:$AU$255,0)),"")) | C22: =IF($A22="","",IFERROR(INDEX('ISV Inventory'!$AA$6:$AA$255,MATCH(SMALL('ISV Inventory'!$AU$6:$AU$255,$A22),'ISV Inventory'!$AU$6:$AU$255,0)),"")) | D22: =IF($A22="","",IFERROR(INDEX('ISV Inventory'!$AB$6:$AB$255,MATCH(SMALL('ISV Inventory'!$AU$6:$AU$255,$A22),'ISV Inventory'!$AU$6:$AU$255,0))&"","")) | E22: =IF($A22="","",IFERROR(INDEX('ISV Inventory'!$B$6:$B$255,MATCH(SMALL('ISV Inventory'!$AU$6:$AU$255,$A22),'ISV Inventory'!$AU$6:$AU$255,0))&"","")) | F22: =IF($A22="","",IFERROR(INDEX('ISV Inventory'!$F$6:$F$255,MATCH(SMALL('ISV Inventory'!$AU$6:$AU$255,$A22),'ISV Inventory'!$AU$6:$AU$255,0))&"","")) | G22: =IF($A22="","",IFERROR(INDEX('ISV Inventory'!$R$6:$R$255,MATCH(SMALL('ISV Inventory'!$AU$6:$AU$255,$A22),'ISV Inventory'!$AU$6:$AU$255,0)),"")) | H22: =IF($A22="","",IFERROR(INDEX('ISV Inventory'!$X$6:$X$255,MATCH(SMALL('ISV Inventory'!$AU$6:$AU$255,$A22),'ISV Inventory'!$AU$6:$AU$255,0))&"","")) | I22: =IF($A22="","",IFERROR(INDEX('ISV Inventory'!$Z$6:$Z$255,MATCH(SMALL('ISV Inventory'!$AU$6:$AU$255,$A22),'ISV Inventory'!$AU$6:$AU$255,0)),"")) | J22: =IF($A22="","",IFERROR(INDEX('ISV Inventory'!$AG$6:$AG$255,MATCH(SMALL('ISV Inventory'!$AU$6:$AU$255,$A22),'ISV Inventory'!$AU$6:$AU$255,0))&"","")) | K22: =IF($A22="","",IFERROR(INDEX('ISV Inventory'!$AK$6:$AK$255,MATCH(SMALL('ISV Inventory'!$AU$6:$AU$255,$A22),'ISV Inventory'!$AU$6:$AU$255,0))&"","")) | L22: =IF($A22="","",IFERROR(INDEX('ISV Inventory'!$AR$6:$AR$255,MATCH(SMALL('ISV Inventory'!$AU$6:$AU$255,$A22),'ISV Inventory'!$AU$6:$AU$255,0))&"","")) | M22: =IF($A22="","",IFERROR(INDEX('ISV Inventory'!$AS$6:$AS$255,MATCH(SMALL('ISV Inventory'!$AU$6:$AU$255,$A22),'ISV Inventory'!$AU$6:$AU$255,0))&"",""))
A23: =IF(COUNT('ISV Inventory'!$AU$6:$AU$255)<19,"",19) | B23: =IF($A23="","",IFERROR(INDEX('ISV Inventory'!$V$6:$V$255,MATCH(SMALL('ISV Inventory'!$AU$6:$AU$255,$A23),'ISV Inventory'!$AU$6:$AU$255,0)),"")) | C23: =IF($A23="","",IFERROR(INDEX('ISV Inventory'!$AA$6:$AA$255,MATCH(SMALL('ISV Inventory'!$AU$6:$AU$255,$A23),'ISV Inventory'!$AU$6:$AU$255,0)),"")) | D23: =IF($A23="","",IFERROR(INDEX('ISV Inventory'!$AB$6:$AB$255,MATCH(SMALL('ISV Inventory'!$AU$6:$AU$255,$A23),'ISV Inventory'!$AU$6:$AU$255,0))&"","")) | E23: =IF($A23="","",IFERROR(INDEX('ISV Inventory'!$B$6:$B$255,MATCH(SMALL('ISV Inventory'!$AU$6:$AU$255,$A23),'ISV Inventory'!$AU$6:$AU$255,0))&"","")) | F23: =IF($A23="","",IFERROR(INDEX('ISV Inventory'!$F$6:$F$255,MATCH(SMALL('ISV Inventory'!$AU$6:$AU$255,$A23),'ISV Inventory'!$AU$6:$AU$255,0))&"","")) | G23: =IF($A23="","",IFERROR(INDEX('ISV Inventory'!$R$6:$R$255,MATCH(SMALL('ISV Inventory'!$AU$6:$AU$255,$A23),'ISV Inventory'!$AU$6:$AU$255,0)),"")) | H23: =IF($A23="","",IFERROR(INDEX('ISV Inventory'!$X$6:$X$255,MATCH(SMALL('ISV Inventory'!$AU$6:$AU$255,$A23),'ISV Inventory'!$AU$6:$AU$255,0))&"","")) | I23: =IF($A23="","",IFERROR(INDEX('ISV Inventory'!$Z$6:$Z$255,MATCH(SMALL('ISV Inventory'!$AU$6:$AU$255,$A23),'ISV Inventory'!$AU$6:$AU$255,0)),"")) | J23: =IF($A23="","",IFERROR(INDEX('ISV Inventory'!$AG$6:$AG$255,MATCH(SMALL('ISV Inventory'!$AU$6:$AU$255,$A23),'ISV Inventory'!$AU$6:$AU$255,0))&"","")) | K23: =IF($A23="","",IFERROR(INDEX('ISV Inventory'!$AK$6:$AK$255,MATCH(SMALL('ISV Inventory'!$AU$6:$AU$255,$A23),'ISV Inventory'!$AU$6:$AU$255,0))&"","")) | L23: =IF($A23="","",IFERROR(INDEX('ISV Inventory'!$AR$6:$AR$255,MATCH(SMALL('ISV Inventory'!$AU$6:$AU$255,$A23),'ISV Inventory'!$AU$6:$AU$255,0))&"","")) | M23: =IF($A23="","",IFERROR(INDEX('ISV Inventory'!$AS$6:$AS$255,MATCH(SMALL('ISV Inventory'!$AU$6:$AU$255,$A23),'ISV Inventory'!$AU$6:$AU$255,0))&"",""))
A24: =IF(COUNT('ISV Inventory'!$AU$6:$AU$255)<20,"",20) | B24: =IF($A24="","",IFERROR(INDEX('ISV Inventory'!$V$6:$V$255,MATCH(SMALL('ISV Inventory'!$AU$6:$AU$255,$A24),'ISV Inventory'!$AU$6:$AU$255,0)),"")) | C24: =IF($A24="","",IFERROR(INDEX('ISV Inventory'!$AA$6:$AA$255,MATCH(SMALL('ISV Inventory'!$AU$6:$AU$255,$A24),'ISV Inventory'!$AU$6:$AU$255,0)),"")) | D24: =IF($A24="","",IFERROR(INDEX('ISV Inventory'!$AB$6:$AB$255,MATCH(SMALL('ISV Inventory'!$AU$6:$AU$255,$A24),'ISV Inventory'!$AU$6:$AU$255,0))&"","")) | E24: =IF($A24="","",IFERROR(INDEX('ISV Inventory'!$B$6:$B$255,MATCH(SMALL('ISV Inventory'!$AU$6:$AU$255,$A24),'ISV Inventory'!$AU$6:$AU$255,0))&"","")) | F24: =IF($A24="","",IFERROR(INDEX('ISV Inventory'!$F$6:$F$255,MATCH(SMALL('ISV Inventory'!$AU$6:$AU$255,$A24),'ISV Inventory'!$AU$6:$AU$255,0))&"","")) | G24: =IF($A24="","",IFERROR(INDEX('ISV Inventory'!$R$6:$R$255,MATCH(SMALL('ISV Inventory'!$AU$6:$AU$255,$A24),'ISV Inventory'!$AU$6:$AU$255,0)),"")) | H24: =IF($A24="","",IFERROR(INDEX('ISV Inventory'!$X$6:$X$255,MATCH(SMALL('ISV Inventory'!$AU$6:$AU$255,$A24),'ISV Inventory'!$AU$6:$AU$255,0))&"","")) | I24: =IF($A24="","",IFERROR(INDEX('ISV Inventory'!$Z$6:$Z$255,MATCH(SMALL('ISV Inventory'!$AU$6:$AU$255,$A24),'ISV Inventory'!$AU$6:$AU$255,0)),"")) | J24: =IF($A24="","",IFERROR(INDEX('ISV Inventory'!$AG$6:$AG$255,MATCH(SMALL('ISV Inventory'!$AU$6:$AU$255,$A24),'ISV Inventory'!$AU$6:$AU$255,0))&"","")) | K24: =IF($A24="","",IFERROR(INDEX('ISV Inventory'!$AK$6:$AK$255,MATCH(SMALL('ISV Inventory'!$AU$6:$AU$255,$A24),'ISV Inventory'!$AU$6:$AU$255,0))&"","")) | L24: =IF($A24="","",IFERROR(INDEX('ISV Inventory'!$AR$6:$AR$255,MATCH(SMALL('ISV Inventory'!$AU$6:$AU$255,$A24),'ISV Inventory'!$AU$6:$AU$255,0))&"","")) | M24: =IF($A24="","",IFERROR(INDEX('ISV Inventory'!$AS$6:$AS$255,MATCH(SMALL('ISV Inventory'!$AU$6:$AU$255,$A24),'ISV Inventory'!$AU$6:$AU$255,0))&"",""))
